Workbook

Sheet Amortization Table
B2: Acquisition Loan | H2: Refinance / Supplemental Loan
B4: Month | C4: Beg Bal | D4: Interest | E4: Principal | F4: End Bal | H4: Month | I4: Beg Bal | J4: Interest | K4: Principal | L4: End Bal
B5: 1 | C5: ='Executive Summary'!C24 -> 5200000 | D5: ='Debt Financing'!$D$3/12*C5 -> 21016.667 | E5: =IF(B5<='Debt Financing'!$D$4,0,'Debt Financing'!$D$7/12-D5) -> 0 | F5: =C5-E5 -> 5200000 | H5: 1 | I5: ='Executive Summary'!$L$18 -> 0 | J5: ='Debt Financing'!$D$27/12*I5 -> 0 | K5: =IF('Executive Summary'!$L$18=0,0,'Debt Financing'!$D$30/12-J5) -> 0 | L5: =I5-K5 -> 0
B6: =+B5+1 -> 2 | C6: =F5 -> 5200000 | D6: ='Debt Financing'!$D$3/12*C6 -> 21016.667 | E6: =IF(B6<='Debt Financing'!$D$4,0,'Debt Financing'!$D$7/12-D6) -> 0 | F6: =C6-E6 -> 5200000 | H6: =+H5+1 -> 2 | I6: =L5 -> 0 | J6: ='Debt Financing'!$D$27/12*I6 -> 0 | K6: =IF('Executive Summary'!$L$18=0,0,'Debt Financing'!$D$30/12-J6) -> 0 | L6: =I6-K6 -> 0
B7: =+B6+1 -> 3 | C7: =F6 -> 5200000 | D7: ='Debt Financing'!$D$3/12*C7 -> 21016.667 | E7: =IF(B7<='Debt Financing'!$D$4,0,'Debt Financing'!$D$7/12-D7) -> 0 | F7: =C7-E7 -> 5200000 | H7: =+H6+1 -> 3 | I7: =L6 -> 0 | J7: ='Debt Financing'!$D$27/12*I7 -> 0 | K7: =IF('Executive Summary'!$L$18=0,0,'Debt Financing'!$D$30/12-J7) -> 0 | L7: =I7-K7 -> 0
B8: =+B7+1 -> 4 | C8: =F7 -> 5200000 | D8: ='Debt Financing'!$D$3/12*C8 -> 21016.667 | E8: =IF(B8<='Debt Financing'!$D$4,0,'Debt Financing'!$D$7/12-D8) -> 0 | F8: =C8-E8 -> 5200000 | H8: =+H7+1 -> 4 | I8: =L7 -> 0 | J8: ='Debt Financing'!$D$27/12*I8 -> 0 | K8: =IF('Executive Summary'!$L$18=0,0,'Debt Financing'!$D$30/12-J8) -> 0 | L8: =I8-K8 -> 0
B9: =+B8+1 -> 5 | C9: =F8 -> 5200000 | D9: ='Debt Financing'!$D$3/12*C9 -> 21016.667 | E9: =IF(B9<='Debt Financing'!$D$4,0,'Debt Financing'!$D$7/12-D9) -> 0 | F9: =C9-E9 -> 5200000 | H9: =+H8+1 -> 5 | I9: =L8 -> 0 | J9: ='Debt Financing'!$D$27/12*I9 -> 0 | K9: =IF('Executive Summary'!$L$18=0,0,'Debt Financing'!$D$30/12-J9) -> 0 | L9: =I9-K9 -> 0
B10: =+B9+1 -> 6 | C10: =F9 -> 5200000 | D10: ='Debt Financing'!$D$3/12*C10 -> 21016.667 | E10: =IF(B10<='Debt Financing'!$D$4,0,'Debt Financing'!$D$7/12-D10) -> 0 | F10: =C10-E10 -> 5200000 | H10: =+H9+1 -> 6 | I10: =L9 -> 0 | J10: ='Debt Financing'!$D$27/12*I10 -> 0 | K10: =IF('Executive Summary'!$L$18=0,0,'Debt Financing'!$D$30/12-J10) -> 0 | L10: =I10-K10 -> 0
B11: =+B10+1 -> 7 | C11: =F10 -> 5200000 | D11: ='Debt Financing'!$D$3/12*C11 -> 21016.667 | E11: =IF(B11<='Debt Financing'!$D$4,0,'Debt Financing'!$D$7/12-D11) -> 0 | F11: =C11-E11 -> 5200000 | H11: =+H10+1 -> 7 | I11: =L10 -> 0 | J11: ='Debt Financing'!$D$27/12*I11 -> 0 | K11: =IF('Executive Summary'!$L$18=0,0,'Debt Financing'!$D$30/12-J11) -> 0 | L11: =I11-K11 -> 0
B12: =+B11+1 -> 8 | C12: =F11 -> 5200000 | D12: ='Debt Financing'!$D$3/12*C12 -> 21016.667 | E12: =IF(B12<='Debt Financing'!$D$4,0,'Debt Financing'!$D$7/12-D12) -> 0 | F12: =C12-E12 -> 5200000 | H12: =+H11+1 -> 8 | I12: =L11 -> 0 | J12: ='Debt Financing'!$D$27/12*I12 -> 0 | K12: =IF('Executive Summary'!$L$18=0,0,'Debt Financing'!$D$30/12-J12) -> 0 | L12: =I12-K12 -> 0
B13: =+B12+1 -> 9 | C13: =F12 -> 5200000 | D13: ='Debt Financing'!$D$3/12*C13 -> 21016.667 | E13: =IF(B13<='Debt Financing'!$D$4,0,'Debt Financing'!$D$7/12-D13) -> 0 | F13: =C13-E13 -> 5200000 | H13: =+H12+1 -> 9 | I13: =L12 -> 0 | J13: ='Debt Financing'!$D$27/12*I13 -> 0 | K13: =IF('Executive Summary'!$L$18=0,0,'Debt Financing'!$D$30/12-J13) -> 0 | L13: =I13-K13 -> 0
B14: =+B13+1 -> 10 | C14: =F13 -> 5200000 | D14: ='Debt Financing'!$D$3/12*C14 -> 21016.667 | E14: =IF(B14<='Debt Financing'!$D$4,0,'Debt Financing'!$D$7/12-D14) -> 0 | F14: =C14-E14 -> 5200000 | H14: =+H13+1 -> 10 | I14: =L13 -> 0 | J14: ='Debt Financing'!$D$27/12*I14 -> 0 | K14: =IF('Executive Summary'!$L$18=0,0,'Debt Financing'!$D$30/12-J14) -> 0 | L14: =I14-K14 -> 0
B15: =+B14+1 -> 11 | C15: =F14 -> 5200000 | D15: ='Debt Financing'!$D$3/12*C15 -> 21016.667 | E15: =IF(B15<='Debt Financing'!$D$4,0,'Debt Financing'!$D$7/12-D15) -> 0 | F15: =C15-E15 -> 5200000 | H15: =+H14+1 -> 11 | I15: =L14 -> 0 | J15: ='Debt Financing'!$D$27/12*I15 -> 0 | K15: =IF('Executive Summary'!$L$18=0,0,'Debt Financing'!$D$30/12-J15) -> 0 | L15: =I15-K15 -> 0
B16: =+B15+1 -> 12 | C16: =F15 -> 5200000 | D16: ='Debt Financing'!$D$3/12*C16 -> 21016.667 | E16: =IF(B16<='Debt Financing'!$D$4,0,'Debt Financing'!$D$7/12-D16) -> 0 | F16: =C16-E16 -> 5200000 | H16: =+H15+1 -> 12 | I16: =L15 -> 0 | J16: ='Debt Financing'!$D$27/12*I16 -> 0 | K16: =IF('Executive Summary'!$L$18=0,0,'Debt Financing'!$D$30/12-J16) -> 0 | L16: =I16-K16 -> 0
B17: =+B16+1 -> 13 | C17: =F16 -> 5200000 | D17: ='Debt Financing'!$D$3/12*C17 -> 21016.667 | E17: =IF(B17<='Debt Financing'!$D$4,0,'Debt Financing'!$D$7/12-D17) -> 0 | F17: =C17-E17 -> 5200000 | H17: =+H16+1 -> 13 | I17: =L16 -> 0 | J17: ='Debt Financing'!$D$27/12*I17 -> 0 | K17: =IF('Executive Summary'!$L$18=0,0,'Debt Financing'!$D$30/12-J17) -> 0 | L17: =I17-K17 -> 0
... B124: =+B123+1 -> 120 | C124: =F123 -> 4481492.5 | D124: ='Debt Financing'!$D$3/12*C124 -> 18112.699 | E124: =IF(B124<='Debt Financing'!$D$4,0,'Debt Financing'!$D$7/12-D124) -> 10207.049 | F124: =C124-E124 -> 4471285.4 | H124: =+H123+1 -> 120 | I124: =L123 -> 0 | J124: ='Debt Financing'!$D$27/12*I124 -> 0 | K124: =IF('Executive Summary'!$L$18=0,0,'Debt Financing'!$D$30/12-J124) -> 0 | L124: =I124-K124 -> 0

Sheet Drop-down List(s)
B2: Closing | D2: Max CF | F2: Yes
B3: Construction | D3: Max IRR | F3: No
B4: Lease-Up
B5: Stabilized
B6: Refinance
B7: Sale

Sheet Executive Summary
B2: Riverhill TH
B4: Property Details: | H4: Growth Assumptions: | K4: Debt Financing Assumptions: | N4: Equity Contributions: | O4: % | P4: Amount
B5: Property Name | C5: Riverhill TH | H5: Rent Growth (Year 1) | I5: ='Cignal Market Read'!$C$43 -> 0.0066 | K5: Acquisition Loan Proceeds | L5: ='Debt Financing'!D17 -> 5200000 | N5: LP Equity | O5: =1-O6 -> 0.9 | P5: =O5*$P$7 -> 1873961.1
B6: Address | C6: 3017 Limestone Drive | H6: Rent Growth (Year 2) | I6: ='Cignal Market Read'!$C$44 -> 0.0326 | K6: Loan-to-Purchase Price | L6: =IFERROR(L5/C30,0) -> 0.78490566 | N6: GP Equity | O6: 0.1 | P6: =O6*$P$7 -> 208217.9
B7: City, State | C7: Louisville, TN | H7: Rent Growth (Subsequent) | I7: ='Cignal Market Read'!$C$45 -> 0.03 | K7: Loan-to-Total Cost | L7: =L5/I23 -> 0.74198266 | N7: Total Equity | O7: =SUM(O5:O6) -> 1 | P7: =C33-C24 -> 2082179
B8: MSA | C8: Knoxville | H8: Other Growth (Year 1) | I8: 0.02 | K8: Interest Rate | L8: 0.0485
B9: Year Built / Renovated | C9: 1982 | H9: Other Growth (Year 2) | I9: 0.02 | K9: Loan Term | L9: 10 | N9: GP Fees:
B10: Construction Type | C10: Frame | H10: Other Growth (Subsequent) | I10: 0.02 | K10: Initial I/O Period | L10: 36 | N10: Acquisition Fee | O10: =C37 -> 0.02 | P10: =D37 -> 132500
B11: # Buildings | C11: 10 | K11: Amortization (after Initial I/O period) | L11: 28 | N11: Equity Placement Fee | O11: =C38 -> 0.02 | P11: =D38 -> 37479.222
B12: # Units | C12: 80 | H12: Exit Assumptions: | K12: Analysis Starting Month | L12: 1 | N12: Asset Management Fee | O12: 0.01 | P12: ='Cash Flow - Monthly'!E149 -> 43342.355
B13: Rentable Square Footage (SF) | C13: 80640 | H13: Hold Period | I13: 60 | K13: Loan Closing Costs | L13: 0 | N13: Disposition Fee | O13: 0 | P13: =O13*I16 -> 0
H14: Exit NOI | I14: ='Cash Flow - Monthly'!E59 -> 606550.05 | K14: Mortgage Insurance Premium | L14: 0
B15: Unit Mix: | H15: Exit Cap Rate | I15: ='Cignal Market Read'!$C$47 -> 0.06770634 | N15: Carried Interest | O15: 0
B16: Type | C16: Count | D16: Avg SF | E16: Market Rent | F16: $ PSF | H16: Gross Sale Proceeds | I16: ='Cash Flow - Monthly'!E120 -> 8958541.5 | K16: Refinance | L16: No
B17: Studio | C17: ='Unit Mix & Comparables'!J51 -> 0 | D17: ='Unit Mix & Comparables'!K51 -> 0 | E17: ='Unit Mix & Comparables'!Q51 -> 0 | F17: =IFERROR(IF(C17, E17/D17, 0),0) -> 0 | H17: Sale Costs | I17: 0.02 | K17: Refinance Month | L17: 0 | N17: Waterfall Assumptions:
B18: 1-BR | C18: ='Unit Mix & Comparables'!J52 -> 0 | D18: ='Unit Mix & Comparables'!K52 -> 0 | E18: ='Unit Mix & Comparables'!Q52 -> 0 | F18: =IFERROR(IF(C18, E18/D18, 0),0) -> 0 | K18: Refinance Proceeds | L18: =IF(L16="No",0,'Debt Financing'!D38) -> 0 | S18: Distribution as %
B19: 2-BR | C19: ='Unit Mix & Comparables'!J53 -> 80 | D19: ='Unit Mix & Comparables'!K53 -> 1008 | E19: ='Unit Mix & Comparables'!Q53 -> 827.225 | F19: =IFERROR(IF(C19, E19/D19, 0),0) -> 0.82065972 | H19: Other Metrics: | K19: LTV | L19: =IF($L$16="No","N/A",IF($K$17="Refinance Month",$L$18/(4*SUM(OFFSET('Cash Flow - Monthly'!$G$55,0,$L$17-1,1,-3))/$I$15),($L$18+'Cash Flow - Monthly'!E98)/C30)) -> N/A | N19: Promote Structure | O19: > __% IRR | P19: Up to __% IRR | Q19: Promote | S19: GP % | T19: LP %
B20: 3-BR + | C20: ='Unit Mix & Comparables'!J54 -> 0 | D20: ='Unit Mix & Comparables'!K54 -> 0 | E20: ='Unit Mix & Comparables'!Q54 -> 0 | F20: =IFERROR(IF(C20, E20/D20, 0),0) -> 0 | H20: Pro Forma Expenses/Unit | I20: ='Operating Inputs'!J36 -> 4311.682 | K20: LTC on Total Cost Basis to Date | L20: =IF($L$16="No","N/A",IF($K$17="Refinance Month",$L$18/(C30+$D$36+$D$43+SUM(OFFSET('Cash Flow - Monthly'!$G$61,0,0,4,$L$17))),($L$18+$L$5)/(C30+$D$36+$D$43+SUM(OFFSET('Cash Flow - Monthly'!$G$61,0,0,4,$L$17))))) -> N/A | N20: Hurdle 1 (Preferred Return) | P20: =O21 -> 0.08 | Q20: GP | R20: LP | S20: =O6 -> 0.1 | T20: =1-S20 -> 0.9
B21: Total/Avg | C21: ='Unit Mix & Comparables'!J55 -> 80 | D21: ='Unit Mix & Comparables'!K55 -> 1008 | E21: =SUMPRODUCT(C17:C20, E17:E20)/SUM(C17:C20) -> 827.225 | F21: =IFERROR(IF(C21, E21/D21, 0),0) -> 0.82065972 | H21: Estimated Replacement Cost | I21: =I30 -> 11808200 | K21: Interest Rate | L21: 0 | N21: Hurdle 2 | O21: 0.08 | P21: =O22 -> 0.1 | Q21: 0.25 | R21: =1-Q21 -> 0.75 | S21: =1-(O5*R21) -> 0.325 | T21: =1-S21 -> 0.675
H22: Total Cost/Replacement Cost | I22: =IFERROR(C33/I21,0) -> 0.61670526 | K22: Loan Term | L22: 0 | N22: Hurdle 3 | O22: 0.1 | P22: =O23 -> 0.12 | Q22: 0.3 | R22: =1-Q22 -> 0.7 | S22: =1-(O5*R22) -> 0.37 | T22: =1-S22 -> 0.63
B23: Sources | C23: $ | D23: $ Per Unit | E23: $ PSF | F23: % | H23: Total Cost | I23: =C30+D39+'Renovation Plan'!O21+'Renovation Plan'!O18+'Renovation Plan'!I35+'Renovation Plan'!J35 -> 7008250 | K23: Initial I/O Period | L23: 0 | N23: Hurdle 4 | O23: 0.12 | Q23: 0.35 | R23: =1-Q23 -> 0.65 | S23: =1-(O5*R23) -> 0.415 | T23: =1-S23 -> 0.585
B24: Senior Debt | C24: ='Debt Financing'!D17 -> 5200000 | D24: =C24/$C$12 -> 65000 | E24: =C24/$C$13 -> 64.484127 | F24: =C24/C$33 -> 0.71407198 | K24: Amortization (after Initial I/O period) | L24: 30
B25: LP Equity (90%) | C25: =P5 -> 1873961.1 | D25: =C25/$C$12 -> 23424.514 | E25: =C25/$C$13 -> 23.238605 | F25: =C25/C$27 -> 0.25733522 | H25: Replacement Cost Estimate: | K25: Refinancing Closing Costs | L25: 0.015 | N25: Investment Performance: | O25: IRR | P25: Equity Multiple | Q25: Peak Capital | R25: Profit | S25: ROI
B26: GP Equity (10%) | C26: =P6 -> 208217.9 | D26: =C26/$C$12 -> 2602.7238 | E26: =C26/$C$13 -> 2.5820672 | F26: =C26/C$27 -> 0.028592802 | H26: Estimated Insurance Cost PSF | I26: 70 | N26: Deal-Level | O26: ='Equity Waterfall - Monthly'!D8 -> 0.20356645 | P26: =1+R26/Q26 -> 2.2452101 | Q26: =-'Cash Flow - Monthly'!G152 -> 2083229.2 | R26: ='Equity Waterfall - Annual'!D7 -> 2594058 | S26: =R26/Q26 -> 1.2452101
B27: Total Sources | C27: =SUM(C24:C26) -> 7282179 | D27: =C27/$C$12 -> 91027.238 | E27: =C27/$C$13 -> 90.304799 | F27: =SUM(F24:F26) -> 1 | H27: Estimated Market Cost PSF | I27: 130 | K27: DSCR: | N27: LP | O27: ='Equity Waterfall - Monthly'!D15 -> #VALUE! | P27: =1+R27/Q27 -> #VALUE! | Q27: =O5*$Q$26 -> 1874906.3 | R27: ='Equity Waterfall - Annual'!D27 -> #VALUE! | S27: =R27/Q27 -> #VALUE!
H28: Estimated Land Value | I28: 1325000 | K28: Trailing-3 Months | L28: ='Debt Financing'!C18 -> 1.2350334 | N28: GP | O28: ='Equity Waterfall - Monthly'!D26 -> #VALUE! | P28: =1+R28/Q28 -> #VALUE! | Q28: =O6*$Q$26 -> 208322.92 | R28: ='Equity Waterfall - Annual'!D22 -> #VALUE! | S28: =R28/Q28 -> #VALUE!
B29: Uses | C29: $ | D29: $ Per Unit | E29: $ PSF | F29: % | H29: Insurance Replacement Cost | I29: =C13*I26 -> 5644800 | K29: Year 1 Pro Forma | L29: =('Operating Inputs'!I38-'Executive Summary'!L36*'Executive Summary'!C12)/-PMT(L8,L11,L5) -> 1.2442006 | N29: Unlevered Returns | O29: =(1+IRR('Cash Flow - Monthly'!G159:EI159,0.1/12))^12-1 -> 0.10165469 | P29: =1+R29/Q29 -> 1.534326 | Q29: =-'Cash Flow - Monthly'!E160 -> 7282179 | R29: ='Cash Flow - Monthly'!E159 -> 3891057.3 | S29: =R29/Q29 -> 0.53432596
B30: Purchase Price | C30: 6625000 | D30: =C30/$C$12 -> 82812.5 | E30: =C30/$C$13 -> 82.155258 | F30: =C30/C$33 -> 0.90975517 | H30: Market Replacement Cost | I30: =C13*I27+I28 -> 11808200 | K30: Stabilized Pro Forma | L30: =('Operating Inputs'!K38-'Executive Summary'!L36*'Executive Summary'!C12)/-PMT(L8,L11,L5) -> 1.3651034
B31: Capital Expenditures | C31: ='Renovation Plan'!I19 -> 383250 | D31: =C31/$C$12 -> 4790.625 | E31: =C31/$C$13 -> 4.7526042 | F31: =C31/C$33 -> 0.052628478 | N31: Cash-on-Cash Return: | O31: Year 1 | P31: Year 2 | Q31: Year 3 | R31: Hold Period
B32: Closing Costs | C32: 273929 | D32: =C32/$C$12 -> 3424.1125 | E32: =C32/$C$13 -> 3.396937 | F32: =C32/C$33 -> 0.037616351 | H32: Property Taxes: | K32: Financing Constraints: | N32: Average | O32: ='Cash Flow - Monthly'!EK157 -> 0.08394162 | P32: ='Cash Flow - Monthly'!EL157 -> 0.10014328 | Q32: ='Cash Flow - Monthly'!EM157 -> 0.11157693 | R32: ='Cash Flow - Monthly'!E157 -> 0.091979767
B33: Total Uses | C33: =SUM(C30:C32) -> 7282179 | D33: =C33/$C$12 -> 91027.238 | E33: =C33/$C$13 -> 90.304799 | F33: =SUM(F30:F32) -> 1 | H33: Appraisal to Purchase Price Ratio | I33: 0.4 | K33: DSCR Constraint
H34: Tax Rate | I34: 0.0247 | K34: NOI (Trailing-12 Months) | L34: ='Operating Inputs'!C38 -> 446567
B35: Closing Costs: | H35: Non-Ad Valorem Taxes and Fees (%) | I35: 0 | K35: DSCR | L35: 1.25
B36: Origination Fee | C36: 0.0075 | D36: =C36*C24 -> 39000 | H36: Non-Ad Valorem Taxes and Fees ($) | I36: =I35*'Operating Inputs'!M20 -> 0 | K36: Reserves/unit | L36: 275
B37: Acquisition Fee | C37: 0.02 | D37: =C37*'Executive Summary'!C30 -> 132500 | H37: Estimated Property Taxes | I37: =C30*I33*I34+I36 -> 65455 | K37: Interest Rate | L37: 0.0485
B38: Equity Placement Fee | C38: 0.02 | D38: =C38*'Executive Summary'!P5 -> 37479.222 | H38: Estimated Year 1 Taxes | I38: =AVERAGE(I37,'Operating Inputs'!C32) -> 60150.5 | K38: Maximum Annual Payment | L38: =(L34-L36*$C$12)/L35 -> 339653.6
B39: Debt Placement Fee | C39: 0 | D39: =C39*'Executive Summary'!C24 -> 0 | K39: Maximum Proceeds | L39: =-PV(L37/12,L11*12,L38/12) -> 5197194.2
B40: Third Party Reports | D40: 20000 | H40: Insurance:
B41: Legal | D41: 20000 | H41: Estimate
B42: Title Costs | D42: 10000 | H42: Rental Income | I42: ='Operating Inputs'!I14 -> 700161.93
...

Sheet Cignal Market Read
B2: CIGNAL · MARKET READ
B3: Forward pro forma assumptions derived from local market performance - not a flat straight-line
B5: Market (MSA) | C5: Knoxville, TN (Knox MSA)
B6: As of | C6: Q2 2026 - illustrative seed; auto-populates from Cignal warehouse in production
B7: Scenario | C7: Base | D7: <- Bear / Base / Bull
B8: Cycle phase (read) | C8: =C48 -> Late Hypersupply -> Recovery (turning up)
B10: A. MARKET INPUTS (from Cignal / editable)
B11: Long-run trend rent growth | C11: 0.03
B12: Employment growth YoY (metro) | C12: 0.012 | E12: Yardi Matrix Apr-2026: +1.2% (2x US 0.6%)
B13: US employment growth (benchmark) | C13: 0.006
B14: Employment / demographic signal (-1..+1) | C14: 0.6 | E14: Emp 2x US; unemployment 2.9%; #1 US in-migration 2026
B15: Rent-momentum signal (-1..+1) | C15: 0.2 | E15: Q2-26 +1.9% - first positive quarter after 3 declines
B16: Absorption / demand signal (-1..+1) | C16: 0.5 | E16: Absorption 592u in Q2, ~3x Q1, 2-yr high
B17: Supply-pressure signal, near-term (-1..+1) | C17: 0.8 | E17: Largest wave in 15y; vacancy 10-yr high; 2,827u under constr.
B18: Supply easing by Year 2 (decay 0..1) | C18: 0.5 | E18: Starts -73%; completions -18% YoY
B19: Current market vacancy | C19: 0.06 | E19: Broad soft; stabilized ~5-6%
B20: Structural (stabilized) vacancy | C20: 0.05
B21: Current 10Y Treasury | C21: 0.043 | E21: FRED DGS10 ~4.3-4.7%
B22: Projected 10Y at exit | C22: 0.043 | E22: Editable rate view
B23: Going-in cap (from deal) | C23: ='Executive Summary'!$C$47 -> 0.06740634 | E23: Linked from Executive Summary
B25: B. ENGINE COEFFICIENTS (MSA-panel calibrated, v2026.08-msapanel-v2 - see Calibration tab)
B26: Rent sensitivity to momentum (k_rent) | C26: 0.065 | E26: Panel elasticities: vacancy -1.7, employment +0.53 (metro FE, R2 0.53)
B27: Vacancy sensitivity to supply (k_vac) | C27: 0.01 | E27: MSA-panel estimate: +0.21 vacancy per 1% of stock permitted (low R2)
B28: Exit-cap rate beta | C28: 0.5 | E28: Literature-anchored; cap~10Y link is loose/regime-dependent
B29: Exit-cap phase sensitivity | C29: 0.01 | E29: Judgmental
B30: Exit-cap conservatism buffer | C30: 0.0035 | E30: Judgmental underwriting buffer
B31: Demand weights: emp / rent-mom / absorption | C31: 0.45 | D31: 0.35 | E31: 0.2
E32: Employment UP-weighted: a strong local rent driver in the panel
B33: C. DERIVATION
B34: Demand Index | C34: =C31*C14+D31*C15+E31*C16 -> 0.44
B35: Supply pressure - Year 1 | C35: =C17 -> 0.8
B36: Supply pressure - Year 2 | C36: =C17*(1-C18) -> 0.4
B37: Momentum - Year 1 | C37: =C34-C35 -> -0.36
B38: Momentum - Year 2 | C38: =C34-C36 -> 0.04
B39: Momentum - at exit | C39: =C34-C17*0.15 -> 0.32
B40: Scenario deltas: rent / vac / cap | C40: =IF(C7="Bear",-0.015,IF(C7="Bull",0.015,0)) -> 0 | D40: =IF(C7="Bear",0.01,IF(C7="Bull",-0.0075,0)) -> 0 | E40: =IF(C7="Bear",0.0035,IF(C7="Bull",-0.0035,0)) -> 0
B42: D. FORWARD ASSUMPTIONS -> feeding the model
B43: Rent Growth - Year 1 | C43: =C11+C37*C26+C40 -> 0.0066
B44: Rent Growth - Year 2 | C44: =C11+C38*C26+C40 -> 0.0326
B45: Rent Growth - Subsequent | C45: =C11+C40 -> 0.03
...

Sheet Exit Strategy
B2: CIGNAL · EXIT STRATEGY — Sell vs. Refinance
B3: Two paths, one cycle-driven recommendation. Sell at hold-end vs. refinance mid-hold and extend.
B5: INPUTS (editable)
B6: Base hold — sell year (Path A) | C6: 5
B7: Refi year (Path B) | C7: 3
B8: Sell year (Path B) | C8: 7
B9: Refi LTV | C9: 0.7
B10: Refi valuation cap | C10: ='Cignal Market Read'!$C$23 -> 0.06740634
B11: Refi interest rate (IO) | C11: 0.055
B12: Refi cost (% of new loan) | C12: 0.01
B13: Sale costs | C13: ='Executive Summary'!$I$17 -> 0.02
B14: Exit cap — Path A | C14: ='Cignal Market Read'!$C$47 -> 0.06770634 | E14: Path B exit cap defaults to same; edit to reflect the phase at the later sale.
B15: Exit cap — Path B (later sale) | C15: ='Cignal Market Read'!$C$47 -> 0.06770634
B17: Equity invested | C17: ='Executive Summary'!$P$5+'Executive Summary'!$P$6 -> 2082179
B18: I/O years / IO DS / Amort DS | C18: ='Executive Summary'!$L$10/12 -> 3 | D18: ='Debt Financing'!$D$8 -> 252200 | E18: ='Debt Financing'!$D$7 -> 339836.97
B20: ANNUAL STREAMS (derived from the model)
B21: Year | D21: 0 | E21: 1 | F21: 2 | G21: 3 | H21: 4 | I21: 5 | J21: 6 | K21: 7 | L21: 8 | M21: 9 | N21: 10 | O21: 11
B22: Net Operating Income | D22: 0 | E22: =SUM('Cash Flow - Monthly'!H55:S55) -> 449219.09 | F22: =SUM('Cash Flow - Monthly'!T55:AE55) -> 483398.6 | G22: =SUM('Cash Flow - Monthly'!AF55:AQ55) -> 507659.15 | H22: =SUM('Cash Flow - Monthly'!AR55:BC55) -> 525544.01 | I22: =SUM('Cash Flow - Monthly'!BD55:BO55) -> 543770.2 | J22: =SUM('Cash Flow - Monthly'!BP55:CA55) -> 606550.05 | K22: =SUM('Cash Flow - Monthly'!CB55:CM55) -> 582029.39 | L22: =SUM('Cash Flow - Monthly'!CN55:CY55) -> 602100.71 | M22: =SUM('Cash Flow - Monthly'!CZ55:DK55) -> 622826.37 | N22: =SUM('Cash Flow - Monthly'!DL55:DW55) -> 644227.06 | O22: =SUM('Cash Flow - Monthly'!DX55:EI55) -> 666324.08
B23: Debt service (original) | D23: 0 | E23: =IF(1<=$C$18,$D$18,$E$18) -> 252200 | F23: =IF(2<=$C$18,$D$18,$E$18) -> 252200 | G23: =IF(3<=$C$18,$D$18,$E$18) -> 252200 | H23: =IF(4<=$C$18,$D$18,$E$18) -> 339836.97 | I23: =IF(5<=$C$18,$D$18,$E$18) -> 339836.97 | J23: =IF(6<=$C$18,$D$18,$E$18) -> 339836.97 | K23: =IF(7<=$C$18,$D$18,$E$18) -> 339836.97 | L23: =IF(8<=$C$18,$D$18,$E$18) -> 339836.97 | M23: =IF(9<=$C$18,$D$18,$E$18) -> 339836.97 | N23: =IF(10<=$C$18,$D$18,$E$18) -> 339836.97
B24: Loan balance (EOY, original) | D24: =$C$17*0+'Executive Summary'!$C$24 -> 5200000 | E24: ='Amortization Table'!F16 -> 5200000 | F24: ='Amortization Table'!F28 -> 5200000 | G24: ='Amortization Table'!F40 -> 5200000 | H24: ='Amortization Table'!F52 -> 5110388.5 | I24: ='Amortization Table'!F64 -> 5016332.8 | J24: ='Amortization Table'!F76 -> 4917612.7 | K24: ='Amortization Table'!F88 -> 4813996.8 | L24: ='Amortization Table'!F100 -> 4705242.3 | M24: ='Amortization Table'!F112 -> 4591094.3 | N24: ='Amortization Table'!F124 -> 4471285.4
B26: REFINANCE SIZING (Path B, at refi year)
B27: NOI at refi+1 | C27: =INDEX($E$22:$O$22,$C$7+1) -> 525544.01
B28: Implied value at refi | C28: =C27/$C$10 -> 7796655.6
B29: New loan | C29: =$C$9*C28 -> 5457658.9
B30: Old loan balance at refi | C30: =INDEX($E$24:$N$24,$C$7) -> 5200000
B31: Cash-out at refi (to equity) | C31: =C29-C30-C29*$C$12 -> 203082.3
B32: New debt service (IO) | C32: =C29*$C$11 -> 300171.24
B33: Net sale proceeds — Path A | C33: =(INDEX($E$22:$O$22,$C$6+1)/$C$14)*(1-$C$13)-INDEX($E$24:$N$24,$C$6) -> 3763037.9
B34: Net sale proceeds — Path B | C34: =(INDEX($E$22:$O$22,$C$8+1)/$C$15)*(1-$C$13)-C29 -> 3257310.7
B36: PATH A — SELL AT HOLD-END
B37: Cash flow to equity | D37: =IF(0=0,-$C$17,IF(0>$C$6,0,(D22-D23)+IF(0=$C$6,$C$33,0))) -> -2082179 | E37: =IF(1=0,-$C$17,IF(1>$C$6,0,(E22-E23)+IF(1=$C$6,$C$33,0))) -> 197019.09 | F37: =IF(2=0,-$C$17,IF(2>$C$6,0,(F22-F23)+IF(2=$C$6,$C$33,0))) -> 231198.6 | G37: =IF(3=0,-$C$17,IF(3>$C$6,0,(G22-G23)+IF(3=$C$6,$C$33,0))) -> 255459.15 | H37: =IF(4=0,-$C$17,IF(4>$C$6,0,(H22-H23)+IF(4=$C$6,$C$33,0))) -> 185707.04 | I37: =IF(5=0,-$C$17,IF(5>$C$6,0,(I22-I23)+IF(5=$C$6,$C$33,0))) -> 3966971.1 | J37: =IF(6=0,-$C$17,IF(6>$C$6,0,(J22-J23)+IF(6=$C$6,$C$33,0))) -> 0 | K37: =IF(7=0,-$C$17,IF(7>$C$6,0,(K22-K23)+IF(7=$C$6,$C$33,0))) -> 0 | L37: =IF(8=0,-$C$17,IF(8>$C$6,0,(L22-L23)+IF(8=$C$6,$C$33,0))) -> 0 | M37: =IF(9=0,-$C$17,IF(9>$C$6,0,(M22-M23)+IF(9=$C$6,$C$33,0))) -> 0 | N37: =IF(10=0,-$C$17,IF(10>$C$6,0,(N22-N23)+IF(10=$C$6,$C$33,0))) -> 0 | O37: =0 -> 0
B39: IRR (levered, deal-level) | C39: =IRR(D37:O37) -> 0.20984125
B40: Equity multiple | C40: =SUM(E37:O37)/$C$17 -> 2.3227374
B41: Total profit | C41: =SUM(E37:O37)-$C$17 -> 2754176
B43: PATH B — REFINANCE MID-HOLD, THEN SELL
B44: Cash flow to equity | D44: =IF(0=0,-$C$17,IF(0>$C$8,0,(IF(0<=$C$7,D22-D23,IF(0<=$C$8,D22-$C$32,0)))+IF(0=$C$7,$C$31,0)+IF(0=$C$8,$C$34,0))) -> -2082179 | E44: =IF(1=0,-$C$17,IF(1>$C$8,0,(IF(1<=$C$7,E22-E23,IF(1<=$C$8,E22-$C$32,0)))+IF(1=$C$7,$C$31,0)+IF(1=$C$8,$C$34,0))) -> 197019.09 | F44: =IF(2=0,-$C$17,IF(2>$C$8,0,(IF(2<=$C$7,F22-F23,IF(2<=$C$8,F22-$C$32,0)))+IF(2=$C$7,$C$31,0)+IF(2=$C$8,$C$34,0))) -> 231198.6 | G44: =IF(3=0,-$C$17,IF(3>$C$8,0,(IF(3<=$C$7,G22-G23,IF(3<=$C$8,G22-$C$32,0)))+IF(3=$C$7,$C$31,0)+IF(3=$C$8,$C$34,0))) -> 458541.45 | H44: =IF(4=0,-$C$17,IF(4>$C$8,0,(IF(4<=$C$7,H22-H23,IF(4<=$C$8,H22-$C$32,0)))+IF(4=$C$7,$C$31,0)+IF(4=$C$8,$C$34,0))) -> 225372.77 | I44: =IF(5=0,-$C$17,IF(5>$C$8,0,(IF(5<=$C$7,I22-I23,IF(5<=$C$8,I22-$C$32,0)))+IF(5=$C$7,$C$31,0)+IF(5=$C$8,$C$34,0))) -> 243598.96 | J44: =IF(6=0,-$C$17,IF(6>$C$8,0,(IF(6<=$C$7,J22-J23,IF(6<=$C$8,J22-$C$32,0)))+IF(6=$C$7,$C$31,0)+IF(6=$C$8,$C$34,0))) -> 306378.82 | K44: =IF(7=0,-$C$17,IF(7>$C$8,0,(IF(7<=$C$7,K22-K23,IF(7<=$C$8,K22-$C$32,0)))+IF(7=$C$7,$C$31,0)+IF(7=$C$8,$C$34,0))) -> 3539168.9 | L44: =IF(8=0,-$C$17,IF(8>$C$8,0,(IF(8<=$C$7,L22-L23,IF(8<=$C$8,L22-$C$32,0)))+IF(8=$C$7,$C$31,0)+IF(8=$C$8,$C$34,0))) -> 0 | M44: =IF(9=0,-$C$17,IF(9>$C$8,0,(IF(9<=$C$7,M22-M23,IF(9<=$C$8,M22-$C$32,0)))+IF(9=$C$7,$C$31,0)+IF(9=$C$8,$C$34,0))) -> 0 | N44: =IF(10=0,-$C$17,IF(10>$C$8,0,(IF(10<=$C$7,N22-N23,IF(10<=$C$8,N22-$C$32,0)))+IF(10=$C$7,$C$31,0)+IF(10=$C$8,$C$34,0))) -> 0 | O44: =0 -> 0
B46: IRR (levered, deal-level) | C46: =IRR(D44:O44) -> 0.17752161
B47: Equity multiple | C47: =SUM(E44:O44)/$C$17 -> 2.4979978
B48: Total profit | C48: =SUM(E44:O44)-$C$17 -> 3119099.6
B50: CIGNAL RECOMMENDATION
...

Sheet Calibration
B2: CIGNAL · ENGINE CALIBRATION (v2026.08-msapanel-v2)
B4: MSA-panel recalibration of the Market Read coefficients — matches the live web engine.
B5: Data: Cignal warehouse, 122 metros, 2015-2026, annual, metro fixed effects (within OLS).
B7: DATA SOURCES
B8: Employment | E8: bls_metro_employment (metro nonfarm employment, YoY %)
B9: Rent (multifamily) | E9: zori_metro_mf (Zillow metro MF asking rent, YoY %)
B10: Vacancy | E10: apt_vacancy (Apartment List metro vacancy rate, %)
B11: Multifamily supply | E11: permits_5plus_metro / acs_housing_units (permits as % of stock)
B12: 10-Year Treasury | E12: FRED DGS10 (national)
B14: FITTED RELATIONSHIPS
B15: Regression | C15: Key coef | D15: R2 | E15: Reading
B16: rent_yoy ~ emp_yoy + vacancy (metro FE) | C16: -1.70 (vac) | D16: 0.53 | E16: Vacancy/slack dominates within-metro
B17: ...employment term | C17: +0.53 (emp) | E17: Employment a STRONG local driver (was +0.05 national)
B18: d_vacancy ~ permits(% stock) (metro FE) | C18: +0.21 | D18: 0.00 | E18: LOCAL supply->vacancy now estimated (low R2)
B20: HOW COEFFICIENTS WERE SET
B21: k_rent | C21: 0.065 | E21: Stronger panel elasticities (vacancy -1.7, employment +0.53)
B22: Demand weights (emp/rent/absorb) | C22: .45/.35/.20 | E22: Employment UP-weighted: strong local driver in the panel
B23: k_vac | C23: 0.010 | E23: Now empirically anchored: panel supply->vacancy +0.21 (modest R2)
B24: Exit-cap rate beta | C24: 0.50 | E24: Unchanged - cap rates not in the panel; literature-anchored
B25: Phase sensitivity / buffer | C25: 0.010 / 35bp | E25: Unchanged - judgmental underwriting parameters
B27: CAVEATS (read before trusting)
B28: • MSA panel with metro fixed effects (122 metros, 2015-2026) - far better identified than national.
B29: • k_vac still has low R2 even locally (supply is noisy) - treat as modest-confidence.
B30: • Vacancy history is shorter (apt_vacancy from 2017); permits stale to 2023.
B31: • Engine v2026.08-msapanel-v2 - matches the live Cignal web Underwriter exactly.

Sheet Debt Financing
B2: Acquisition Financing Assumptions
B3: Interest Rate | D3: ='Executive Summary'!L8 -> 0.0485
B4: Initial I/O Period | D4: ='Executive Summary'!L10 -> 36
B5: Amortization (after initial I/O period) | D5: ='Executive Summary'!L11 -> 28
B6: NOI (Trailing-3 Months) | D6: ='Operating Inputs'!G38 -> 419710
B7: Annual Debt Service (Amortizing) | D7: =-PMT(D3/12,D5*12,D17)*12 -> 339836.97
B8: Annual Debt Service (Interest-Only) | D8: =D3*D17 -> 252200
B9: Loan Sizing:
B10: Debt Yield | C10: 0.08 | D10: =(D6-'Executive Summary'!L36*'Executive Summary'!C12)/C10 -> 4971375
B11: LTC / LTV | C11: 0.75 | D11: =C11*'Executive Summary'!C33 -> 5461634.2
B12: LTPP | C12: 0.75 | D12: =C12*'Executive Summary'!C30 -> 4968750
B13: DSCR | C13: 1.2 | D13: =-PV(D3/12,30*12,(D6-'Executive Summary'!L36*'Executive Summary'!C12)/C13/12) -> 5233878.7
B14: Assumable Loan Amount | C14: - | D14: 0
B15: Actual Loan Amount:
B16: Debt Yield | C16: =D6/D17 -> 0.080713462
B17: LTC / LTV | C17: =D17/'Executive Summary'!C33 -> 0.71407198 | D17: 5200000
B18: DSCR (Amortizing) | C18: =D6/D7 -> 1.2350334
B20: Balloon Balance at Refinance | D20: =IF('Executive Summary'!L17=0,"N/A",IPMT('Debt Financing'!D3/12,'Executive Summary'!L17-'Debt Financing'!D4+1,'Debt Financing'!D5*12,-'Debt Financing'!D17)/('Debt Financing'!D3/12)) -> N/A
B21: Balloon Balance at Maturity | D21: =IPMT('Debt Financing'!D3/12,'Executive Summary'!I13-'Debt Financing'!D4+1,'Debt Financing'!D5*12,-'Debt Financing'!D17)/('Debt Financing'!D3/12) -> 5016332.8
B23: Refinance Assumptions
B24: Refinance Month | D24: =IF('Executive Summary'!L17=0,"N/A",'Executive Summary'!L17) -> N/A
B25: NOI (Trailing-3 Months) | D25: =IF(D24="N/A","N/A",4*SUM(OFFSET('Cash Flow - Monthly'!$G$55,0,'Executive Summary'!$L$17-1,1,-3))) -> N/A
B26: Implied Valuation | D26: =IF(D24="N/A","N/A",D25/'Executive Summary'!I15) -> N/A
B27: Interest Rate | D27: ='Executive Summary'!L21 -> 0
B28: Initial I/O Period | D28: ='Executive Summary'!L23 -> 0
B29: Amortization | D29: 30
B30: Annual Debt Service (Amortizing) | D30: =IF(D24="N/A","N/A",-PMT(D27/12,D29*12,D38)*12) -> N/A
B31: Annual Debt Service (Interest-Only) | D31: =IF(D24="N/A","N/A",D27*D38) -> N/A
B32: Loan Sizing:
B33: Debt Yield | C33: 0.08 | D33: =IF(D24="N/A","N/A",D25/C33) -> N/A
B34: LTV | C34: 0.75 | D34: =IF(D24="N/A","N/A",C34*D26) -> N/A
B35: DSCR | C35: 1.3 | D35: =IF(D24="N/A","N/A",-PV(D27/12,30*12,D25/C35/12)) -> N/A
B36: Actual Loan Amount:
B37: Debt Yield | C37: =IF(D24="N/A","N/A",D25/D38) -> N/A
B38: LTC / LTV | C38: =IF(D24="N/A","N/A",D38/D26) -> N/A | D38: =MIN(D33:D35) -> 0
B39: DSCR (Amortizing) | C39: =IF(D24="N/A","N/A",D25/D30) -> N/A
B41: Balloon Balance at Maturity | D41: =IF('Debt Financing'!$D$27=0,"N/A",IPMT('Debt Financing'!$D$27/12,'Executive Summary'!L22*12+1,'Debt Financing'!$D$29*12,-'Debt Financing'!$D$38)/('Debt Financing'!$D$27/12)) -> N/A

Sheet Operating Inputs
B2: ='Executive Summary'!B2 -> Riverhill TH
B3: Operating Inputs
C4: T-12 | E4: T-3 Annualized | G4: T-3 Rev / T12 Exp | I4: Pro Forma (Year 1) | K4: Pro Forma (Year 2) | M4: Pro Forma (Adj T-12) | P4: Assumptions
C5: (ended 11/17) | D5: % / $/Unit | E5: (ended 11/17) | F5: % / $/Unit | G5: (ended 11/17) | H5: % / $/Unit | I5: Total | J5: % / $/Unit | K5: Total | L5: % / $/Unit | M5: Total | N5: % / $/Unit
B6: REVENUES
B7: Rental Income
B8: Market Rent | C8: 728750 | D8: =C8/C$10 -> 1.0215768 | E8: ='T-3 Worksheet'!G7 -> 732624 | F8: =E8/E$10 -> 1.0240073 | G8: =E8 -> 732624 | H8: =G8/G$10 -> 1.0240073 | I8: ='Cash Flow - Monthly'!EK25 -> 761762.48 | J8: =I8/I$10 -> 1.0203376 | K8: ='Cash Flow - Monthly'!EL25 -> 807389.08 | L8: =K8/K$10 -> 1.0152686 | M8: =SUMPRODUCT('Unit Mix & Comparables'!C9:C38,'Unit Mix & Comparables'!G9:G38)*12 -> 746136 | N8: =M8/M$10 -> 1.0152284
B9: Gain (Loss) to Lease | C9: -15392 | D9: =C9/C$10 -> -0.021576824 | E9: ='T-3 Worksheet'!G8 -> -17176 | F9: =E9/E$10 -> -0.024007335 | G9: =E9 -> -17176 | H9: =G9/G$10 -> -0.024007335 | I9: ='Cash Flow - Monthly'!EK26 -> -15183.619 | J9: =I9/I$10 -> -0.020337596 | K9: ='Cash Flow - Monthly'!EL26 -> -12142.277 | L9: =K9/K$10 -> -0.015268564 | M9: =-('Executive Summary'!I7/2)*M8 -> -11192.04 | N9: =M9/M$10 -> -0.015228426
B10: Gross Potential Rent | C10: =SUM(C8:C9) -> 713358 | D10: =C10/C$10 -> 1 | E10: =SUM(E8:E9) -> 715448 | F10: =E10/E$10 -> 1 | G10: =SUM(G8:G9) -> 715448 | H10: =G10/G$10 -> 1 | I10: =SUM(I8:I9) -> 746578.86 | J10: =I10/I$10 -> 1 | K10: =SUM(K8:K9) -> 795246.8 | L10: =K10/K$10 -> 1 | M10: =SUM(M8:M9) -> 734943.96 | N10: =M10/M$10 -> 1 | P10: Economic Loss (%)
B11: Rental Losses | C11: 0 | D11: =C11/C$10 -> 0 | E11: ='T-3 Worksheet'!G14 -> 0 | F11: =E11/E$10 -> 0 | G11: =E11 -> 0 | H11: =G11/G$10 -> 0 | I11: ='Cash Flow - Monthly'!EK28 -> -2239.7366 | J11: =I11/I$10 -> -0.003 | K11: ='Cash Flow - Monthly'!EL28 -> -2385.7404 | L11: =K11/K$10 -> -0.003 | M11: =P11*$M$10 -> -2204.8319 | N11: =M11/M$10 -> -0.003 | P11: -0.003
B12: Vacancy | C12: -20449 | D12: =C12/C$10 -> -0.028665831 | E12: ='T-3 Worksheet'!G12 -> -49488 | F12: =E12/E$10 -> -0.069170646 | G12: =E12 -> -49488 | H12: =G12/G$10 -> -0.069170646 | I12: ='Cash Flow - Monthly'!EK29 -> -41937.452 | J12: =I12/I$10 -> -0.056172836 | K12: ='Cash Flow - Monthly'!EL29 -> -44533.821 | L12: =K12/K$10 -> -0.056 | M12: =P12*$M$10 -> -41156.862 | N12: =M12/M$10 -> -0.056 | P12: =-'Cignal Market Read'!$C$46 -> -0.056
B13: Bad Debt | C13: -12 | D13: =C13/C$10 -> -1.6821848e-05 | E13: ='T-3 Worksheet'!G15 -> -6068 | F13: =E13/E$10 -> -0.0084813991 | G13: =E13 -> -6068 | H13: =G13/G$10 -> -0.0084813991 | I13: ='Cash Flow - Monthly'!EK30 -> -2239.7366 | J13: =I13/I$10 -> -0.003 | K13: ='Cash Flow - Monthly'!EL30 -> -2385.7404 | L13: =K13/K$10 -> -0.003 | M13: =P13*$M$10 -> -2204.8319 | N13: =M13/M$10 -> -0.003 | P13: -0.003
B14: Net Rental Income | C14: =SUM(C10:C13) -> 692897 | D14: =C14/C$10 -> 0.97131735 | E14: =SUM(E10:E13) -> 659892 | F14: =E14/E$10 -> 0.92234796 | G14: =SUM(G10:G13) -> 659892 | H14: =G14/G$10 -> 0.92234796 | I14: =SUM(I10:I13) -> 700161.93 | J14: =I14/I$10 -> 0.93782716 | K14: =SUM(K10:K13) -> 745941.5 | L14: =K14/K$10 -> 0.938 | M14: =SUM(M10:M13) -> 689377.43 | N14: =M14/M$10 -> 0.938
B15: Other Income | P15: Unit Per Year
B16: Utility | C16: 37188 | D16: =C16/'Executive Summary'!$C$12 -> 464.85 | E16: ='T-3 Worksheet'!G18 -> 39684 | F16: =E16/'Executive Summary'!$C$12 -> 496.05 | G16: =E16 -> 39684 | H16: =G16/'Executive Summary'!$C$12 -> 496.05 | I16: ='Cash Flow - Monthly'!EK33 -> 41097.592 | J16: =I16/'Executive Summary'!$C$12 -> 513.7199 | K16: ='Cash Flow - Monthly'!EL33 -> 41919.543 | L16: =K16/'Executive Summary'!$C$12 -> 523.99429 | M16: =P16*M28 -> 43200 | N16: =M16/'Executive Summary'!$C$12 -> 540 | P16: 0.9
B17: Late Charges | C17: 5853 | D17: =C17/'Executive Summary'!$C$12 -> 73.1625 | E17: ='T-3 Worksheet'!G19 -> 5168 | F17: =E17/'Executive Summary'!$C$12 -> 64.6 | G17: =E17 -> 5168 | H17: =G17/'Executive Summary'!$C$12 -> 64.6 | I17: ='Cash Flow - Monthly'!EK34 -> 5327.4656 | J17: =I17/'Executive Summary'!$C$12 -> 66.59332 | K17: ='Cash Flow - Monthly'!EL34 -> 5434.0149 | L17: =K17/'Executive Summary'!$C$12 -> 67.925186 | M17: =P17*'Executive Summary'!$C$12 -> 5600 | N17: =M17/'Executive Summary'!$C$12 -> 70 | P17: 70
B18: Other | C18: 48159 | D18: =C18/'Executive Summary'!$C$12 -> 601.9875 | E18: ='T-3 Worksheet'!G20 -> 52496 | F18: =E18/'Executive Summary'!$C$12 -> 656.2 | G18: =E18 -> 52496 | H18: =G18/'Executive Summary'!$C$12 -> 656.2 | I18: ='Cash Flow - Monthly'!EK35 -> 47566.657 | J18: =I18/'Executive Summary'!$C$12 -> 594.58321 | K18: ='Cash Flow - Monthly'!EL35 -> 48517.99 | L18: =K18/'Executive Summary'!$C$12 -> 606.47488 | M18: =P18*'Executive Summary'!$C$12 -> 50000 | N18: =M18/'Executive Summary'!$C$12 -> 625 | P18: 625
B19: Total Other Income | C19: =SUM(C16:C18) -> 91200 | D19: =C19/'Executive Summary'!$C$12 -> 1140 | E19: =SUM(E16:E18) -> 97348 | F19: =E19/'Executive Summary'!$C$12 -> 1216.85 | G19: =SUM(G16:G18) -> 97348 | H19: =G19/'Executive Summary'!$C$12 -> 1216.85 | I19: =SUM(I16:I18) -> 93991.714 | J19: =I19/'Executive Summary'!$C$12 -> 1174.8964 | K19: =SUM(K16:K18) -> 95871.549 | L19: =K19/'Executive Summary'!$C$12 -> 1198.3944 | M19: =SUM(M16:M18) -> 98800 | N19: =M19/'Executive Summary'!$C$12 -> 1235
B20: TOTAL REVENUES | C20: =SUM(C14,C19) -> 784097 | D20: =C20/'Executive Summary'!$C$12 -> 9801.2125 | E20: =SUM(E14,E19) -> 757240 | F20: =E20/'Executive Summary'!$C$12 -> 9465.5 | G20: =SUM(G14,G19) -> 757240 | H20: =G20/'Executive Summary'!$C$12 -> 9465.5 | I20: =SUM(I14,I19) -> 794153.65 | J20: =I20/'Executive Summary'!$C$12 -> 9926.9206 | K20: =SUM(K14,K19) -> 841813.05 | L20: =K20/'Executive Summary'!$C$12 -> 10522.663 | M20: =SUM(M14,M19) -> 788177.43 | N20: =M20/'Executive Summary'!$C$12 -> 9852.2179
B22: EXPENSES
B23: Controllable | P23: $/Unit/Year
B24: Payroll | C24: 108802 | D24: =C24/'Executive Summary'!$C$12 -> 1360.025 | E24: ='T-3 Worksheet'!G26 -> 114772 | F24: =E24/'Executive Summary'!$C$12 -> 1434.65 | G24: =C24 -> 108802 | H24: =G24/'Executive Summary'!$C$12 -> 1360.025 | I24: ='Cash Flow - Monthly'!EK41 -> 88950.449 | J24: =I24/'Executive Summary'!$C$12 -> 1111.8806 | K24: ='Cash Flow - Monthly'!EL41 -> 90729.458 | L24: =K24/'Executive Summary'!$C$12 -> 1134.1182 | M24: =N24*'Executive Summary'!$C$12 -> 88000 | N24: =P24 -> 1100 | P24: 1100
B25: Operations & Maintenance | C25: 55527 | D25: =C25/'Executive Summary'!$C$12 -> 694.0875 | E25: ='T-3 Worksheet'!G27 -> 60488 | F25: =E25/'Executive Summary'!$C$12 -> 756.1 | G25: =C25 -> 55527 | H25: =G25/'Executive Summary'!$C$12 -> 694.0875 | I25: ='Cash Flow - Monthly'!EK42 -> 60648.034 | J25: =I25/'Executive Summary'!$C$12 -> 758.10042 | K25: ='Cash Flow - Monthly'!EL42 -> 61860.994 | L25: =K25/'Executive Summary'!$C$12 -> 773.26243 | M25: =N25*'Executive Summary'!$C$12 -> 60000 | N25: =P25 -> 750 | P25: 750
B26: Marketing | C26: 12212 | D26: =C26/'Executive Summary'!$C$12 -> 152.65 | E26: ='T-3 Worksheet'!G28 -> 13136 | F26: =E26/'Executive Summary'!$C$12 -> 164.2 | G26: =C26 -> 12212 | H26: =G26/'Executive Summary'!$C$12 -> 152.65 | I26: ='Cash Flow - Monthly'!EK43 -> 14151.208 | J26: =I26/'Executive Summary'!$C$12 -> 176.8901 | K26: ='Cash Flow - Monthly'!EL43 -> 14434.232 | L26: =K26/'Executive Summary'!$C$12 -> 180.4279 | M26: =N26*'Executive Summary'!$C$12 -> 14000 | N26: =P26 -> 175 | P26: 175
B27: General & Adminstrative | C27: 13957 | D27: =C27/'Executive Summary'!$C$12 -> 174.4625 | E27: ='T-3 Worksheet'!G29 -> 26076 | F27: =E27/'Executive Summary'!$C$12 -> 325.95 | G27: =C27 -> 13957 | H27: =G27/'Executive Summary'!$C$12 -> 174.4625 | I27: ='Cash Flow - Monthly'!EK44 -> 24259.213 | J27: =I27/'Executive Summary'!$C$12 -> 303.24017 | K27: ='Cash Flow - Monthly'!EL44 -> 24744.398 | L27: =K27/'Executive Summary'!$C$12 -> 309.30497 | M27: =N27*'Executive Summary'!$C$12 -> 24000 | N27: =P27 -> 300 | P27: 300
B28: Utilities: Reimbursable | C28: 43667 | D28: =C28/'Executive Summary'!$C$12 -> 545.8375 | E28: ='T-3 Worksheet'!G30 -> 49840 | F28: =E28/'Executive Summary'!$C$12 -> 623 | G28: =C28 -> 43667 | H28: =G28/'Executive Summary'!$C$12 -> 545.8375 | I28: ='Cash Flow - Monthly'!EK45 -> 48518.427 | J28: =I28/'Executive Summary'!$C$12 -> 606.48034 | K28: ='Cash Flow - Monthly'!EL45 -> 49488.795 | L28: =K28/'Executive Summary'!$C$12 -> 618.60994 | M28: =N28*'Executive Summary'!$C$12 -> 48000 | N28: =P28 -> 600 | P28: 600
B29: Utilities: Other | C29: 2611 | D29: =C29/'Executive Summary'!$C$12 -> 32.6375 | E29: ='T-3 Worksheet'!G31 -> 4108 | F29: =E29/'Executive Summary'!$C$12 -> 51.35 | G29: =C29 -> 2611 | H29: =G29/'Executive Summary'!$C$12 -> 32.6375 | I29: ='Cash Flow - Monthly'!EK46 -> 3638.882 | J29: =I29/'Executive Summary'!$C$12 -> 45.486025 | K29: ='Cash Flow - Monthly'!EL46 -> 3711.6597 | L29: =K29/'Executive Summary'!$C$12 -> 46.395746 | M29: =N29*'Executive Summary'!$C$12 -> 3600 | N29: =P29 -> 45 | P29: 45
B30: Total Controllable | C30: =SUM(C24:C29) -> 236776 | D30: =C30/'Executive Summary'!$C$12 -> 2959.7 | E30: =SUM(E24:E29) -> 268420 | F30: =E30/'Executive Summary'!$C$12 -> 3355.25 | G30: =SUM(G24:G29) -> 236776 | H30: =G30/'Executive Summary'!$C$12 -> 2959.7 | I30: =SUM(I24:I29) -> 240166.21 | J30: =I30/'Executive Summary'!$C$12 -> 3002.0777 | K30: =SUM(K24:K29) -> 244969.54 | L30: =K30/'Executive Summary'!$C$12 -> 3062.1192 | M30: =SUM(M24:M29) -> 237600 | N30: =SUM(N24:N29) -> 2970
B31: Noncontrollable
B32: Taxes | C32: 54846 | D32: =C32/'Executive Summary'!$C$12 -> 685.575 | E32: ='T-3 Worksheet'!G34 -> 54964 | F32: =E32/'Executive Summary'!$C$12 -> 687.05 | G32: =C32 -> 54846 | H32: =G32/'Executive Summary'!$C$12 -> 685.575 | I32: ='Cash Flow - Monthly'!EK49 -> 60800.159 | J32: =I32/'Executive Summary'!$C$12 -> 760.00199 | K32: ='Executive Summary'!I38 -> 60150.5 | L32: =K32/'Executive Summary'!$C$12 -> 751.88125 | M32: ='Executive Summary'!I38 -> 60150.5 | N32: =M32/'Executive Summary'!$C$12 -> 751.88125
B33: Insurance | C33: 22037 | D33: =C33/'Executive Summary'!$C$12 -> 275.4625 | E33: ='T-3 Worksheet'!G35 -> 24912 | F33: =E33/'Executive Summary'!$C$12 -> 311.4 | G33: =C33 -> 22037 | H33: =G33/'Executive Summary'!$C$12 -> 275.4625 | I33: ='Cash Flow - Monthly'!EK50 -> 16172.809 | J33: =I33/'Executive Summary'!$C$12 -> 202.16011 | K33: ='Cash Flow - Monthly'!EL50 -> 16496.265 | L33: =K33/'Executive Summary'!$C$12 -> 206.20331 | M33: =IF('Executive Summary'!I55>0,'Executive Summary'!I55,'Executive Summary'!I49) -> 16000 | N33: =M33/'Executive Summary'!$C$12 -> 200 | P33: % of Total Revenue
B34: Property Management Fee | C34: 23871 | D34: =C34/'Executive Summary'!$C$12 -> 298.3875 | E34: ='T-3 Worksheet'!G36 -> 18016 | F34: =E34/'Executive Summary'!$C$12 -> 225.2 | G34: =C34 -> 23871 | H34: =G34/'Executive Summary'!$C$12 -> 298.3875 | I34: ='Cash Flow - Monthly'!EK51 -> 27795.378 | J34: =I34/'Executive Summary'!$C$12 -> 347.44222 | K34: ='Cash Flow - Monthly'!EL51 -> 29463.457 | L34: =K34/'Executive Summary'!$C$12 -> 368.29321 | M34: =P34*M20 -> 27586.21 | N34: =M34/'Executive Summary'!$C$12 -> 344.82763 | P34: 0.035
B35: Total Noncontrollable | C35: =SUM(C32:C34) -> 100754 | D35: =C35/'Executive Summary'!$C$12 -> 1259.425 | E35: =SUM(E32:E34) -> 97892 | F35: =E35/'Executive Summary'!$C$12 -> 1223.65 | G35: =SUM(G32:G34) -> 100754 | H35: =G35/'Executive Summary'!$C$12 -> 1259.425 | I35: =SUM(I32:I34) -> 104768.35 | J35: =I35/'Executive Summary'!$C$12 -> 1309.6043 | K35: =SUM(K32:K34) -> 106110.22 | L35: =K35/'Executive Summary'!$C$12 -> 1326.3778 | M35: =SUM(M32:M34) -> 103736.71 | N35: =M35/'Executive Summary'!$C$12 -> 1296.7089
B36: TOTAL EXPENSES | C36: =SUM(C30,C35) -> 337530 | D36: =C36/'Executive Summary'!$C$12 -> 4219.125 | E36: =SUM(E30,E35) -> 366312 | F36: =E36/'Executive Summary'!$C$12 -> 4578.9 | G36: =SUM(G30,G35) -> 337530 | H36: =G36/'Executive Summary'!$C$12 -> 4219.125 | I36: =SUM(I30,I35) -> 344934.56 | J36: =I36/'Executive Summary'!$C$12 -> 4311.682 | K36: =SUM(K30,K35) -> 351079.76 | L36: =K36/'Executive Summary'!$C$12 -> 4388.497 | M36: =SUM(M30,M35) -> 341336.71 | N36: =M36/'Executive Summary'!$C$12 -> 4266.7089 | P36: =M36/M20 -> 0.4330709
B38: NET OPERATING INCOME | C38: =C20-C36 -> 446567 | D38: =C38/'Executive Summary'!$C$12 -> 5582.0875 | E38: =E20-E36 -> 390928 | F38: =E38/'Executive Summary'!$C$12 -> 4886.6 | G38: =G20-G36 -> 419710 | H38: =G38/'Executive Summary'!$C$12 -> 5246.375 | I38: =I20-I36 -> 449219.09 | J38: =I38/'Executive Summary'!$C$12 -> 5615.2386 | K38: =K20-K36 -> 490733.29 | L38: =K38/'Executive Summary'!$C$12 -> 6134.1662 | M38: =M20-M36 -> 446840.72 | N38: =M38/'Executive Summary'!$C$12 -> 5585.5091
B40: Yield on Purchase Price | C40: =IFERROR(C38/'Executive Summary'!$C$30,0) -> 0.06740634 | E40: =IFERROR(E38/'Executive Summary'!$C$30,0) -> 0.059008 | G40: =IFERROR(G38/'Executive Summary'!$C$30,0) -> 0.063352453 | I40: =IFERROR(I38/'Executive Summary'!$C$30,0) -> 0.067806655 | K40: =IFERROR(K38/'Executive Summary'!$C$30,0) -> 0.07407295 | M40: =IFERROR(M38/'Executive Summary'!$C$30,0) -> 0.067447656
B41: Yield on Total Cost | C41: =IFERROR(C38/'Executive Summary'!$I$23,0) -> 0.063720187 | E41: =IFERROR(E38/'Executive Summary'!$I$23,0) -> 0.055781115 | G41: =IFERROR(G38/'Executive Summary'!$I$23,0) -> 0.059887989 | I41: =IFERROR(I38/'Executive Summary'!$I$23,0) -> 0.064098611 | K41: =IFERROR(K38/'Executive Summary'!$I$23,0) -> 0.07002223 | M41: =IFERROR(M38/'Executive Summary'!$I$23,0) -> 0.063759244
B42: Return on Equity [3] | C42: =(C38+'Cash Flow - Monthly'!$H$74*12-'Cash Flow - Monthly'!$H$65*12)/'Executive Summary'!$P$7 -> 0.082764577 | E42: =(E38+'Cash Flow - Monthly'!$H$74*12-'Cash Flow - Monthly'!$H$65*12)/'Executive Summary'!$P$7 -> 0.056043052 | G42: =(G38+'Cash Flow - Monthly'!$H$74*12-'Cash Flow - Monthly'!$H$65*12)/'Executive Summary'!$P$7 -> 0.069866071 | I42: =(I38+'Cash Flow - Monthly'!$H$74*12-'Cash Flow - Monthly'!$H$65*12)/'Executive Summary'!$P$7 -> 0.084038286 | K42: =(K38+'Cash Flow - Monthly'!$H$74*12-'Cash Flow - Monthly'!$H$65*12)/'Executive Summary'!$P$7 -> 0.10397615 | M42: =(M38+'Cash Flow - Monthly'!$H$74*12-'Cash Flow - Monthly'!$H$65*12)/'Executive Summary'!$P$7 -> 0.082896038
B44: [1] T3 Adjusted is T3 income and Controllable expenses annualized, and pro forma Taxes, Insurance, and Management Fee.
B45: [2] Assumptions are pro forma numbers without factoring in any market growth or inflation projections or Y1 adjustments.
...

Sheet T-3 Worksheet
B2: ='Executive Summary'!B2 -> Riverhill TH
B3: T-3 Worksheet
C4: 1 | D4: 2 | E4: 3 | F4: Total | G4: Annualized
B5: REVENUES
B6: Rental Income
B7: Rent Revenue | C7: 60647 | D7: 60656 | E7: 61853 | F7: =SUM(C7:E7) -> 183156 | G7: =F7/3*12 -> 732624
B8: Gain (Loss) to Lease | C8: -2255 | D8: -130 | E8: -1909 | F8: =SUM(C8:E8) -> -4294 | G8: =F8/3*12 -> -17176
B9: Gross Potential Rent | C9: =SUM(C7:C8) -> 58392 | D9: =SUM(D7:D8) -> 60526 | E9: =SUM(E7:E8) -> 59944 | F9: =SUM(F7:F8) -> 178862 | G9: =F9/3*12 -> 715448
B11: Vacancy Rate | C11: =ABS(C12/C9) -> 0.080045212 | D11: =ABS(D12/D9) -> 0.088870898 | E11: =ABS(E12/E9) -> 0.038686107 | F11: =ABS(F12/F9) -> 0.069170646 | G11: =ABS(G12/G9) -> 0.069170646
B12: Total Vacancy | C12: -4674 | D12: -5379 | E12: -2319 | F12: =SUM(C12:E12) -> -12372 | G12: =F12/3*12 -> -49488
B14: Rental Losses | C14: 0 | D14: 0 | E14: 0 | F14: =SUM(C14:E14) -> 0 | G14: =F14/3*12 -> 0
B15: Bad Debt | C15: -1058 | D15: -220 | E15: -239 | F15: =SUM(C15:E15) -> -1517 | G15: =F15/3*12 -> -6068
B16: Net Rental Income | C16: =SUM(C9,C12,C14:C15) -> 52660 | D16: =SUM(D9,D12,D14:D15) -> 54927 | E16: =SUM(E9,E12,E14:E15) -> 57386 | F16: =SUM(F9,F12,F14:F15) -> 164973 | G16: =F16/3*12 -> 659892
B17: Other Income
B18: Utility Reimbursements | C18: 3469 | D18: 3126 | E18: 3326 | F18: =SUM(C18:E18) -> 9921 | G18: =F18/3*12 -> 39684
B19: Late Fees | C19: 690 | D19: 448 | E19: 154 | F19: =SUM(C19:E19) -> 1292 | G19: =F19/3*12 -> 5168
B20: Other | C20: 4405 | D20: 3797 | E20: 4922 | F20: =SUM(C20:E20) -> 13124 | G20: =F20/3*12 -> 52496
B21: Total Other Income | C21: =SUM(C18:C20) -> 8564 | D21: =SUM(D18:D20) -> 7371 | E21: =SUM(E18:E20) -> 8402 | F21: =SUM(F18:F20) -> 24337 | G21: =F21/3*12 -> 97348
B22: TOTAL REVENUES | C22: =SUM(C16,C21) -> 61224 | D22: =SUM(D16,D21) -> 62298 | E22: =SUM(E16,E21) -> 65788 | F22: =SUM(F16,F21) -> 189310 | G22: =F22/3*12 -> 757240
B24: EXPENSES
B25: Controllable
B26: Payroll | C26: 11393 | D26: 8182 | E26: 9118 | F26: =SUM(C26:E26) -> 28693 | G26: =F26/3*12 -> 114772
B27: Operations & Maintenance | C27: 4919 | D27: 4800 | E27: 5403 | F27: =SUM(C27:E27) -> 15122 | G27: =F27/3*12 -> 60488
B28: Marketing | C28: 1192 | D28: 1010 | E28: 1082 | F28: =SUM(C28:E28) -> 3284 | G28: =F28/3*12 -> 13136
B29: General & Administrative | C29: 2846 | D29: 2431 | E29: 1242 | F29: =SUM(C29:E29) -> 6519 | G29: =F29/3*12 -> 26076
B30: Utilities: Reimbursable | C30: 3655 | D30: 4111 | E30: 4694 | F30: =SUM(C30:E30) -> 12460 | G30: =F30/3*12 -> 49840
B31: Utilities: Other | C31: 478 | D31: 220 | E31: 329 | F31: =SUM(C31:E31) -> 1027 | G31: =F31/3*12 -> 4108
B32: Total Controllable | C32: =SUM(C26:C31) -> 24483 | D32: =SUM(D26:D31) -> 20754 | E32: =SUM(E26:E31) -> 21868 | F32: =SUM(F26:F31) -> 67105 | G32: =F32/3*12 -> 268420
B33: Noncontrollable | G33: =F33/3*12 -> 0
B34: Taxes | C34: 4621 | D34: 4560 | E34: 4560 | F34: =SUM(C34:E34) -> 13741 | G34: =F34/3*12 -> 54964
B35: Insurance | C35: 2311 | D35: 1646 | E35: 2271 | F35: =SUM(C35:E35) -> 6228 | G35: =F35/3*12 -> 24912
B36: Property Management Fee | C36: 768 | D36: 1738 | E36: 1998 | F36: =SUM(C36:E36) -> 4504 | G36: =F36/3*12 -> 18016
B37: Total Noncontrollable | C37: =SUM(C34:C36) -> 7700 | D37: =SUM(D34:D36) -> 7944 | E37: =SUM(E34:E36) -> 8829 | F37: =SUM(C37:E37) -> 24473 | G37: =F37/3*12 -> 97892
B38: TOTAL EXPENSES | C38: =SUM(C32,C37) -> 32183 | D38: =SUM(D32,D37) -> 28698 | E38: =SUM(E32,E37) -> 30697 | F38: =SUM(F32,F37) -> 91578 | G38: =F38/3*12 -> 366312
B40: NET OPERATING INCOME | C40: =C22-C38 -> 29041 | D40: =D22-D38 -> 33600 | E40: =E22-E38 -> 35091 | F40: =SUM(C40:E40) -> 97732 | G40: =F40/3*12 -> 390928

Sheet Unit Mix & Comparables
B2: ='Cash Flow - Monthly'!B2 -> Riverhill TH
B3: Unit Mix & Comparables
B5: Post Renovation | C5: Subject Pro Forma | I5: Subject Current | R5: Comparable #1 | X5: Comparable #2 | AD5: Comparable #3 | AJ5: Comparable #4 | AP5: Comparable #5 | AV5: Comparable #6 | BB5: Comparable #7
B6: Property Name | C6: ='Executive Summary'!$C$5 -> Riverhill TH | H6: B | I6: ='Executive Summary'!$C$5 -> Riverhill TH | Q6: B | R6: Johnathan's Ridge | W6: B | X6: Riverside Manor | AC6: B | AD6: Windy Lakes | AI6: B | AJ6: Riverside South | AO6: B | AP6: Country View | AU6: B | AV6: Camellia Trace | BA6: B | BB6: Bridgeway
B7: Age | C7: ='Executive Summary'!$C$9 -> 1982 | I7: ='Executive Summary'!$C$9 -> 1982 | O7: Pre Reno | P7: Avg-Reno Premium | R7: 1982 | X7: 1985 | AD7: 1979 | AJ7: 1988 | AP7: 1993 | AV7: 2004 | BB7: 2012
C8: Count | D8: Beds | E8: Baths | F8: SF | G8: $ | H8: $/SF | I8: Count | J8: Beds | K8: Baths | L8: SF | M8: $ | N8: $/SF | O8: Variance | R8: Count | S8: Beds | T8: Baths | U8: SF | V8: $ | W8: $/SF | X8: Count | Y8: Beds | Z8: Baths | AA8: SF | AB8: $ | AC8: $/SF | AD8: Count | AE8: Beds | AF8: Baths | AG8: SF | AH8: $ | AI8: $/SF | AJ8: Count | AK8: Beds | AL8: Baths | AM8: SF | AN8: $ | AO8: $/SF | AP8: Count | AQ8: Beds | AR8: Baths | AS8: SF | AT8: $ | AU8: $/SF | AV8: Count | AW8: Beds | AX8: Baths | AY8: SF | AZ8: $ | BA8: $/SF | BB8: Count | BC8: Beds | BD8: Baths | BE8: SF | BF8: $ | BG8: $/SF
B9: 2BD/1.5TH | C9: 2 | D9: 2 | E9: 1.5 | F9: 1008 | G9: 729 | H9: =IFERROR(IF(C9, G9/F9, 0),0) -> 0.72321429 | I9: =IF(C9<>"",C9,"") -> 2 | J9: =IF(D9<>"",D9,"") -> 2 | K9: =IF(E9<>"",E9,"") -> 1.5 | L9: =IF(F9<>"",F9,"") -> 1008 | M9: 703 | N9: =IFERROR(IF(I9, M9/L9, 0),0) -> 0.69742063 | O9: =G9-M9 -> 26 | P9: ='Unit Reno Premium Comp'!F5-'Unit Mix & Comparables'!G9 -> 98 | R9: 50 | S9: 2 | T9: 1 | U9: 950 | V9: 650 | W9: =IFERROR(IF(R9, V9/U9, 0),0) -> 0.68421053 | X9: 25 | Y9: 1 | Z9: 1 | AA9: 570 | AB9: 345 | AC9: =IFERROR(IF(X9, AB9/AA9, 0),0) -> 0.60526316 | AD9: 50 | AE9: 1 | AF9: 1 | AG9: 700 | AH9: 430 | AI9: =IFERROR(IF(AD9, AH9/AG9, 0),0) -> 0.61428571 | AJ9: 25 | AK9: 0 | AL9: 1 | AM9: 500 | AN9: 375 | AO9: =IFERROR(IF(AJ9, AN9/AM9, 0),0) -> 0.75 | AP9: 25 | AQ9: 1 | AR9: 1 | AS9: 450 | AT9: 395 | AU9: =IFERROR(IF(AP9, AT9/AS9, 0),0) -> 0.87777778 | AV9: 25 | AW9: 1 | AX9: 1 | AY9: 671 | AZ9: 776 | BA9: =IFERROR(IF(AV9, AZ9/AY9, 0),0) -> 1.1564829 | BG9: =IFERROR(IF(BB9, BF9/BE9, 0),0) -> 0
B10: 2BD/1.5TH-D | C10: 15 | D10: 2 | E10: 1.5 | F10: 1008 | G10: 772 | H10: =IFERROR(IF(C10, G10/F10, 0),0) -> 0.76587302 | I10: =IF(C10<>"",C10,"") -> 15 | J10: =IF(D10<>"",D10,"") -> 2 | K10: =IF(E10<>"",E10,"") -> 1.5 | L10: =IF(F10<>"",F10,"") -> 1008 | M10: 772 | N10: =IFERROR(IF(I10, M10/L10, 0),0) -> 0.76587302 | O10: =G10-M10 -> 0 | P10: ='Unit Reno Premium Comp'!F6-'Unit Mix & Comparables'!G10 -> 55 | R10: 50 | S10: 2 | T10: 1 | U10: 95 | V10: 690 | W10: =IFERROR(IF(R10, V10/U10, 0),0) -> 7.2631579 | X10: 25 | Y10: 1 | Z10: 1 | AA10: 620 | AB10: 380 | AC10: =IFERROR(IF(X10, AB10/AA10, 0),0) -> 0.61290323 | AD10: 50 | AE10: 2 | AF10: 1 | AG10: 950 | AH10: 530 | AI10: =IFERROR(IF(AD10, AH10/AG10, 0),0) -> 0.55789474 | AJ10: 25 | AK10: 1 | AL10: 1 | AM10: 583 | AN10: 404 | AO10: =IFERROR(IF(AJ10, AN10/AM10, 0),0) -> 0.69296741 | AP10: 25 | AQ10: 2 | AR10: 1 | AS10: 720 | AT10: 495 | AU10: =IFERROR(IF(AP10, AT10/AS10, 0),0) -> 0.6875 | AV10: 25 | AW10: 1 | AX10: 1 | AY10: 772 | AZ10: 836 | BA10: =IFERROR(IF(AV10, AZ10/AY10, 0),0) -> 1.0829016 | BG10: =IFERROR(IF(BB10, BF10/BE10, 0),0) -> 0
B11: 2BD/1.5TH-P | C11: 63 | D11: 2 | E11: 1.5 | F11: 1008 | G11: 780 | H11: =IFERROR(IF(C11, G11/F11, 0),0) -> 0.77380952 | I11: =IF(C11<>"",C11,"") -> 63 | J11: =IF(D11<>"",D11,"") -> 2 | K11: =IF(E11<>"",E11,"") -> 1.5 | L11: =IF(F11<>"",F11,"") -> 1008 | M11: 778 | N11: =IFERROR(IF(I11, M11/L11, 0),0) -> 0.7718254 | O11: =G11-M11 -> 2 | P11: 0 | W11: =IFERROR(IF(R11, V11/U11, 0),0) -> 0 | X11: 25 | Y11: 1 | Z11: 1 | AA11: 640 | AB11: 390 | AC11: =IFERROR(IF(X11, AB11/AA11, 0),0) -> 0.609375 | AI11: =IFERROR(IF(AD11, AH11/AG11, 0),0) -> 0 | AJ11: 25 | AK11: 2 | AL11: 1 | AM11: 750 | AN11: 457 | AO11: =IFERROR(IF(AJ11, AN11/AM11, 0),0) -> 0.60933333 | AP11: 25 | AQ11: 2 | AR11: 1 | AS11: 828 | AT11: 525 | AU11: =IFERROR(IF(AP11, AT11/AS11, 0),0) -> 0.63405797 | AV11: 25 | AW11: 1 | AX11: 1 | AY11: 907 | AZ11: 886 | BA11: =IFERROR(IF(AV11, AZ11/AY11, 0),0) -> 0.97684675 | BG11: =IFERROR(IF(BB11, BF11/BE11, 0),0) -> 0
H12: =IFERROR(IF(C12, G12/F12, 0),0) -> 0 | I12: =IF(C12<>"",C12,"") | J12: =IF(D12<>"",D12,"") | K12: =IF(E12<>"",E12,"") | L12: =IF(F12<>"",F12,"") | N12: =IFERROR(IF(I12, M12/L12, 0),0) -> 0 | O12: =G12-M12 -> 0 | P12: 0 | W12: =IFERROR(IF(R12, V12/U12, 0),0) -> 0 | X12: 25 | Y12: 2 | Z12: 1 | AA12: 680 | AB12: 400 | AC12: =IFERROR(IF(X12, AB12/AA12, 0),0) -> 0.58823529 | AI12: =IFERROR(IF(AD12, AH12/AG12, 0),0) -> 0 | AJ12: 25 | AK12: 3 | AL12: 1 | AM12: 878 | AN12: 565 | AO12: =IFERROR(IF(AJ12, AN12/AM12, 0),0) -> 0.64350797 | AU12: =IFERROR(IF(AP12, AT12/AS12, 0),0) -> 0 | AV12: 25 | AW12: 2 | AX12: 2 | AY12: 1197 | AZ12: 946 | BA12: =IFERROR(IF(AV12, AZ12/AY12, 0),0) -> 0.79030911 | BG12: =IFERROR(IF(BB12, BF12/BE12, 0),0) -> 0
H13: =IFERROR(IF(C13, G13/F13, 0),0) -> 0 | I13: =IF(C13<>"",C13,"") | J13: =IF(D13<>"",D13,"") | K13: =IF(E13<>"",E13,"") | L13: =IF(F13<>"",F13,"") | N13: =IFERROR(IF(I13, M13/L13, 0),0) -> 0 | O13: =G13-M13 -> 0 | P13: ='Unit Reno Premium Comp'!F9-'Unit Mix & Comparables'!G13 -> 0 | W13: =IFERROR(IF(R13, V13/U13, 0),0) -> 0 | X13: 25 | Y13: 2 | Z13: 1 | AA13: 740 | AB13: 425 | AC13: =IFERROR(IF(X13, AB13/AA13, 0),0) -> 0.57432432 | AI13: =IFERROR(IF(AD13, AH13/AG13, 0),0) -> 0 | AJ13: 25 | AK13: 4 | AL13: 2 | AM13: 1560 | AN13: 750 | AO13: =IFERROR(IF(AJ13, AN13/AM13, 0),0) -> 0.48076923 | AU13: =IFERROR(IF(AP13, AT13/AS13, 0),0) -> 0 | AV13: 25 | AW13: 2 | AX13: 2 | AY13: 1208 | AZ13: 996 | BA13: =IFERROR(IF(AV13, AZ13/AY13, 0),0) -> 0.82450331 | BG13: =IFERROR(IF(BB13, BF13/BE13, 0),0) -> 0
H14: =IFERROR(IF(C14, G14/F14, 0),0) -> 0 | I14: =IF(C14<>"",C14,"") | J14: =IF(D14<>"",D14,"") | K14: =IF(E14<>"",E14,"") | L14: =IF(F14<>"",F14,"") | N14: =IFERROR(IF(I14, M14/L14, 0),0) -> 0 | O14: =G14-M14 -> 0 | P14: ='Unit Reno Premium Comp'!F10-'Unit Mix & Comparables'!G14 -> 0 | W14: =IFERROR(IF(R14, V14/U14, 0),0) -> 0 | X14: 25 | Y14: 2 | Z14: 1 | AA14: 750 | AB14: 430 | AC14: =IFERROR(IF(X14, AB14/AA14, 0),0) -> 0.57333333 | AI14: =IFERROR(IF(AD14, AH14/AG14, 0),0) -> 0 | AO14: =IFERROR(IF(AJ14, AN14/AM14, 0),0) -> 0 | AU14: =IFERROR(IF(AP14, AT14/AS14, 0),0) -> 0 | AV14: 25 | AW14: 3 | AX14: 2 | AY14: 1414 | AZ14: 1206 | BA14: =IFERROR(IF(AV14, AZ14/AY14, 0),0) -> 0.85289958 | BG14: =IFERROR(IF(BB14, BF14/BE14, 0),0) -> 0
H15: =IFERROR(IF(C15, G15/F15, 0),0) -> 0 | I15: =IF(C15<>"",C15,"") | J15: =IF(D15<>"",D15,"") | K15: =IF(E15<>"",E15,"") | L15: =IF(F15<>"",F15,"") | N15: =IFERROR(IF(I15, M15/L15, 0),0) -> 0 | O15: =G15-M15 -> 0 | P15: ='Unit Reno Premium Comp'!F11-'Unit Mix & Comparables'!G15 -> 0 | W15: =IFERROR(IF(R15, V15/U15, 0),0) -> 0 | X15: 25 | Y15: 2 | Z15: 1 | AA15: 860 | AB15: 435 | AC15: =IFERROR(IF(X15, AB15/AA15, 0),0) -> 0.50581395 | AI15: =IFERROR(IF(AD15, AH15/AG15, 0),0) -> 0 | AO15: =IFERROR(IF(AJ15, AN15/AM15, 0),0) -> 0 | AU15: =IFERROR(IF(AP15, AT15/AS15, 0),0) -> 0 | BA15: =IFERROR(IF(AV15, AZ15/AY15, 0),0) -> 0 | BG15: =IFERROR(IF(BB15, BF15/BE15, 0),0) -> 0
H16: =IFERROR(IF(C16, G16/F16, 0),0) -> 0 | I16: =IF(C16<>"",C16,"") | J16: =IF(D16<>"",D16,"") | K16: =IF(E16<>"",E16,"") | L16: =IF(F16<>"",F16,"") | N16: =IFERROR(IF(I16, M16/L16, 0),0) -> 0 | O16: =G16-M16 -> 0 | P16: ='Unit Reno Premium Comp'!F12-'Unit Mix & Comparables'!G16 -> 0 | W16: =IFERROR(IF(R16, V16/U16, 0),0) -> 0 | X16: 25 | Y16: 3 | Z16: 1 | AA16: 875 | AB16: 460 | AC16: =IFERROR(IF(X16, AB16/AA16, 0),0) -> 0.52571429 | AI16: =IFERROR(IF(AD16, AH16/AG16, 0),0) -> 0 | AO16: =IFERROR(IF(AJ16, AN16/AM16, 0),0) -> 0 | AU16: =IFERROR(IF(AP16, AT16/AS16, 0),0) -> 0 | BA16: =IFERROR(IF(AV16, AZ16/AY16, 0),0) -> 0 | BG16: =IFERROR(IF(BB16, BF16/BE16, 0),0) -> 0
H17: =IFERROR(IF(C17, G17/F17, 0),0) -> 0 | I17: =IF(C17<>"",C17,"") | J17: =IF(D17<>"",D17,"") | K17: =IF(E17<>"",E17,"") | L17: =IF(F17<>"",F17,"") | N17: =IFERROR(IF(I17, M17/L17, 0),0) -> 0 | O17: =G17-M17 -> 0 | P17: ='Unit Reno Premium Comp'!F13-'Unit Mix & Comparables'!G17 -> 0 | W17: =IFERROR(IF(R17, V17/U17, 0),0) -> 0 | AC17: =IFERROR(IF(X17, AB17/AA17, 0),0) -> 0 | AI17: =IFERROR(IF(AD17, AH17/AG17, 0),0) -> 0 | AO17: =IFERROR(IF(AJ17, AN17/AM17, 0),0) -> 0 | AU17: =IFERROR(IF(AP17, AT17/AS17, 0),0) -> 0 | BA17: =IFERROR(IF(AV17, AZ17/AY17, 0),0) -> 0 | BG17: =IFERROR(IF(BB17, BF17/BE17, 0),0) -> 0
H18: =IFERROR(IF(C18, G18/F18, 0),0) -> 0 | I18: =IF(C18<>"",C18,"") | J18: =IF(D18<>"",D18,"") | K18: =IF(E18<>"",E18,"") | L18: =IF(F18<>"",F18,"") | N18: =IFERROR(IF(I18, M18/L18, 0),0) -> 0 | O18: =G18-M18 -> 0 | P18: ='Unit Reno Premium Comp'!F14-'Unit Mix & Comparables'!G18 -> 0 | W18: =IFERROR(IF(R18, V18/U18, 0),0) -> 0 | AC18: =IFERROR(IF(X18, AB18/AA18, 0),0) -> 0 | AI18: =IFERROR(IF(AD18, AH18/AG18, 0),0) -> 0 | AO18: =IFERROR(IF(AJ18, AN18/AM18, 0),0) -> 0 | AU18: =IFERROR(IF(AP18, AT18/AS18, 0),0) -> 0 | BA18: =IFERROR(IF(AV18, AZ18/AY18, 0),0) -> 0 | BG18: =IFERROR(IF(BB18, BF18/BE18, 0),0) -> 0
H19: =IFERROR(IF(C19, G19/F19, 0),0) -> 0 | I19: =IF(C19<>"",C19,"") | J19: =IF(D19<>"",D19,"") | K19: =IF(E19<>"",E19,"") | L19: =IF(F19<>"",F19,"") | N19: =IFERROR(IF(I19, M19/L19, 0),0) -> 0 | O19: =G19-M19 -> 0 | P19: ='Unit Reno Premium Comp'!F15-'Unit Mix & Comparables'!G19 -> 0 | W19: =IFERROR(IF(R19, V19/U19, 0),0) -> 0 | AC19: =IFERROR(IF(X19, AB19/AA19, 0),0) -> 0 | AI19: =IFERROR(IF(AD19, AH19/AG19, 0),0) -> 0 | AO19: =IFERROR(IF(AJ19, AN19/AM19, 0),0) -> 0 | AU19: =IFERROR(IF(AP19, AT19/AS19, 0),0) -> 0 | BA19: =IFERROR(IF(AV19, AZ19/AY19, 0),0) -> 0 | BG19: =IFERROR(IF(BB19, BF19/BE19, 0),0) -> 0
H20: =IFERROR(IF(C20, G20/F20, 0),0) -> 0 | I20: =IF(C20<>"",C20,"") | J20: =IF(D20<>"",D20,"") | K20: =IF(E20<>"",E20,"") | L20: =IF(F20<>"",F20,"") | N20: =IFERROR(IF(I20, M20/L20, 0),0) -> 0 | O20: =G20-M20 -> 0 | P20: ='Unit Reno Premium Comp'!F16-'Unit Mix & Comparables'!G20 -> 0 | AU20: =IFERROR(IF(AP20, AT20/AS20, 0),0) -> 0 | BG20: =IFERROR(IF(BB20, BF20/BE20, 0),0) -> 0
H21: =IFERROR(IF(C21, G21/F21, 0),0) -> 0 | I21: =IF(C21<>"",C21,"") | J21: =IF(D21<>"",D21,"") | K21: =IF(E21<>"",E21,"") | L21: =IF(F21<>"",F21,"") | N21: =IFERROR(IF(I21, M21/L21, 0),0) -> 0 | O21: =G21-M21 -> 0 | P21: ='Unit Reno Premium Comp'!F17-'Unit Mix & Comparables'!G21 -> 0 | AU21: =IFERROR(IF(AP21, AT21/AS21, 0),0) -> 0 | BG21: =IFERROR(IF(BB21, BF21/BE21, 0),0) -> 0
H22: =IFERROR(IF(C22, G22/F22, 0),0) -> 0 | I22: =IF(C22<>"",C22,"") | J22: =IF(D22<>"",D22,"") | K22: =IF(E22<>"",E22,"") | L22: =IF(F22<>"",F22,"") | N22: =IFERROR(IF(I22, M22/L22, 0),0) -> 0 | O22: =G22-M22 -> 0 | P22: ='Unit Reno Premium Comp'!F18-'Unit Mix & Comparables'!G22 -> 0 | AU22: =IFERROR(IF(AP22, AT22/AS22, 0),0) -> 0 | BG22: =IFERROR(IF(BB22, BF22/BE22, 0),0) -> 0
H23: =IFERROR(IF(C23, G23/F23, 0),0) -> 0 | I23: =IF(C23<>"",C23,"") | J23: =IF(D23<>"",D23,"") | K23: =IF(E23<>"",E23,"") | L23: =IF(F23<>"",F23,"") | N23: =IFERROR(IF(I23, M23/L23, 0),0) -> 0 | O23: =G23-M23 -> 0 | P23: ='Unit Reno Premium Comp'!F19-'Unit Mix & Comparables'!G23 -> 0 | AU23: =IFERROR(IF(AP23, AT23/AS23, 0),0) -> 0 | BG23: =IFERROR(IF(BB23, BF23/BE23, 0),0) -> 0
H24: =IFERROR(IF(C24, G24/F24, 0),0) -> 0 | I24: =IF(C24<>"",C24,"") | J24: =IF(D24<>"",D24,"") | K24: =IF(E24<>"",E24,"") | L24: =IF(F24<>"",F24,"") | N24: =IFERROR(IF(I24, M24/L24, 0),0) -> 0 | O24: =G24-M24 -> 0 | P24: ='Unit Reno Premium Comp'!F20-'Unit Mix & Comparables'!G24 -> 0 | AU24: =IFERROR(IF(AP24, AT24/AS24, 0),0) -> 0 | BG24: =IFERROR(IF(BB24, BF24/BE24, 0),0) -> 0
H25: =IFERROR(IF(C25, G25/F25, 0),0) -> 0 | I25: =IF(C25<>"",C25,"") | J25: =IF(D25<>"",D25,"") | K25: =IF(E25<>"",E25,"") | L25: =IF(F25<>"",F25,"") | N25: =IFERROR(IF(I25, M25/L25, 0),0) -> 0 | O25: =G25-M25 -> 0 | P25: ='Unit Reno Premium Comp'!F21-'Unit Mix & Comparables'!G25 -> 0 | AU25: =IFERROR(IF(AP25, AT25/AS25, 0),0) -> 0 | BG25: =IFERROR(IF(BB25, BF25/BE25, 0),0) -> 0
